Workbook

Sheet 說明與假設
A1: 《僱傭條例》「連續性合約」468規定 — 滾動核查與年假試算說明
A3: 一、法規依據
A4: 2025年12月立法會通過《2025年僱傭(修訂)條例》，修訂「連續性合約」定義（俗稱「468規定」），
A5: 已於 2026年1月18日 起生效，取代舊有「418規定」。由於本檔案工時數據涵蓋期間為
A6: 2026/03/01 – 2026/07/31，全期均適用新的「468規定」，毋須處理新舊制過渡問題。
A8: 僱員符合「連續性合約」的條件（EO 附表 1A）：
A9: (1) 連續受僱於同一僱主4個星期或以上；並
A10: (2) 在該星期內工作至少17小時；或
A11: (3) 若該星期工時少於17小時，該星期連同緊接之前3個星期合計工時達68小時或以上。
A12: 即條件(2)或(3)其一成立即可，且屬「滾動式」逐星期核查（每星期都要用「本週+前3週」重新計算一次）。
A14: 二、本試算採用的假設（請與HR/薪酬同事核對）
A15: 1. 「星期」定義：以每位員工在本檔案中首次出現的日期作為第1週起點，其後每7天為一週，
... A45: 報告產生日期：2026/08/03

Sheet 獨立驗算參考值
A1: 本工作紙由另一支獨立 Python 程式（採用與「468滾動核查明細」公式完全相同的判定邏輯）直接讀取原始工時資料計算得出，用作交叉比對。由於目前製作環境的 LibreOffice 無法自動重新計算公式快取值，請在 Excel／Numbers／Google Sheets 開啟本檔案後，確認「468滾動核查明細」與「年假資格與試算總表」兩張工作紙自動重新計算後的數值，與本表一致。
A2: 工號 | B2: 姓名 | C2: 資料首見日期 | D2: 資料涵蓋至 | E2: 累計符合468天數(所有期間) | F2: 歷來最長單一連續期(天) | G2: 目前(最新一週)是否在連續期內 | H2: 目前連續期累計天數 | I2: 按比例年假估算天數(=7×連續天數/365,已達90天門檻者)
A3: P0026 | B3: 李芷彤 | C3: 2026/03/01 | D3: 2026/07/31 | E3: 104 | F3: 35 | G3: 是(僅6天,新起始) | H3: 6 | I3: 0
A4: P0027 | B4: 陳詩祺 | C4: 2026/03/01 | D4: 2026/07/31 | E4: 56 | F4: 14 | G4: 否(已中斷) | H4: 0 | I4: 0
A5: P0028 | B5: 盧天欣 | C5: 2026/03/01 | D5: 2026/07/31 | E5: 63 | F5: 28 | G5: 否(已中斷) | H5: 0 | I5: 0
A6: P0029 | B6: 林惠嫻 | C6: 2026/03/01 | D6: 2026/03/26 | E6: 5 | F6: 5 | G6: 資料不足(僅26天,末週未滿7天,無法確定) | H6: 5 | I6: 0
A7: P0030 | B7: 周夏愉 | C7: 2026/03/09 | D7: 2026/07/31 | E7: 56 | F7: 28 | G7: 否(已中斷) | H7: 0 | I7: 0
A8: P0031 | B8: 梁綽恩 | C8: 2026/03/01 | D8: 2026/07/31 | E8: 111 | F8: 111 | G8: 是,持續中 | H8: 111 | I8: 2.1

Sheet 年假資格與試算總表
A1: 工號 | B1: 姓名 | C1: 資料首見日期(假設為到職日) | D1: 資料涵蓋至 | E1: 資料涵蓋總天數 | F1: 累計符合468連續性合約天數(所有期間加總) | G1: 累計符合468連續性合約週數 | H1: 歷來最長單一連續期(天) | I1: 最新一週是否仍在連續期內 | J1: 目前連續期累計天數(遇中斷則為0) | K1: 是否已達3個月(90天)門檻 | L1: 按比例年假估算天數 =7×連續天數/365 | M1: 備註
A2: P0026 | B2: 李芷彤 | C2: =MINIFS(個人班表!$D$2:$D$785,個人班表!$B$2:$B$785,$A2) | D2: =MAXIFS(個人班表!$D$2:$D$785,個人班表!$B$2:$B$785,$A2) | E2: =DATEDIF(DATEVALUE(SUBSTITUTE($C2,"/","-")),DATEVALUE(SUBSTITUTE($D2,"/","-")),"d")+1 | F2: =SUMIFS('468滾動核查明細'!$M$2:$M$114,'468滾動核查明細'!$A$2:$A$114,$A2) | G2: =COUNTIFS('468滾動核查明細'!$A$2:$A$114,$A2,'468滾動核查明細'!$L$2:$L$114,"是") | H2: =MAXIFS('468滾動核查明細'!$O$2:$O$114,'468滾動核查明細'!$A$2:$A$114,$A2) | I2: =LOOKUP(2,1/('468滾動核查明細'!$A$2:$A$114=$A2),'468滾動核查明細'!$L$2:$L$114) | J2: =LOOKUP(2,1/('468滾動核查明細'!$A$2:$A$114=$A2),'468滾動核查明細'!$O$2:$O$114) | K2: =IF(J2>=90,"是","否") | L2: =IF(K2="是",ROUND(7*J2/365,1),0)
A3: P0027 | B3: 陳詩祺 | C3: =MINIFS(個人班表!$D$2:$D$785,個人班表!$B$2:$B$785,$A3) | D3: =MAXIFS(個人班表!$D$2:$D$785,個人班表!$B$2:$B$785,$A3) | E3: =DATEDIF(DATEVALUE(SUBSTITUTE($C3,"/","-")),DATEVALUE(SUBSTITUTE($D3,"/","-")),"d")+1 | F3: =SUMIFS('468滾動核查明細'!$M$2:$M$114,'468滾動核查明細'!$A$2:$A$114,$A3) | G3: =COUNTIFS('468滾動核查明細'!$A$2:$A$114,$A3,'468滾動核查明細'!$L$2:$L$114,"是") | H3: =MAXIFS('468滾動核查明細'!$O$2:$O$114,'468滾動核查明細'!$A$2:$A$114,$A3) | I3: =LOOKUP(2,1/('468滾動核查明細'!$A$2:$A$114=$A3),'468滾動核查明細'!$L$2:$L$114) | J3: =LOOKUP(2,1/('468滾動核查明細'!$A$2:$A$114=$A3),'468滾動核查明細'!$O$2:$O$114) | K3: =IF(J3>=90,"是","否") | L3: =IF(K3="是",ROUND(7*J3/365,1),0)
A4: P0028 | B4: 盧天欣 | C4: =MINIFS(個人班表!$D$2:$D$785,個人班表!$B$2:$B$785,$A4) | D4: =MAXIFS(個人班表!$D$2:$D$785,個人班表!$B$2:$B$785,$A4) | E4: =DATEDIF(DATEVALUE(SUBSTITUTE($C4,"/","-")),DATEVALUE(SUBSTITUTE($D4,"/","-")),"d")+1 | F4: =SUMIFS('468滾動核查明細'!$M$2:$M$114,'468滾動核查明細'!$A$2:$A$114,$A4) | G4: =COUNTIFS('468滾動核查明細'!$A$2:$A$114,$A4,'468滾動核查明細'!$L$2:$L$114,"是") | H4: =MAXIFS('468滾動核查明細'!$O$2:$O$114,'468滾動核查明細'!$A$2:$A$114,$A4) | I4: =LOOKUP(2,1/('468滾動核查明細'!$A$2:$A$114=$A4),'468滾動核查明細'!$L$2:$L$114) | J4: =LOOKUP(2,1/('468滾動核查明細'!$A$2:$A$114=$A4),'468滾動核查明細'!$O$2:$O$114) | K4: =IF(J4>=90,"是","否") | L4: =IF(K4="是",ROUND(7*J4/365,1),0)
A5: P0029 | B5: 林惠嫻 | C5: =MINIFS(個人班表!$D$2:$D$785,個人班表!$B$2:$B$785,$A5) | D5: =MAXIFS(個人班表!$D$2:$D$785,個人班表!$B$2:$B$785,$A5) | E5: =DATEDIF(DATEVALUE(SUBSTITUTE($C5,"/","-")),DATEVALUE(SUBSTITUTE($D5,"/","-")),"d")+1 | F5: =SUMIFS('468滾動核查明細'!$M$2:$M$114,'468滾動核查明細'!$A$2:$A$114,$A5) | G5: =COUNTIFS('468滾動核查明細'!$A$2:$A$114,$A5,'468滾動核查明細'!$L$2:$L$114,"是") | H5: =MAXIFS('468滾動核查明細'!$O$2:$O$114,'468滾動核查明細'!$A$2:$A$114,$A5) | I5: =LOOKUP(2,1/('468滾動核查明細'!$A$2:$A$114=$A5),'468滾動核查明細'!$L$2:$L$114) | J5: =LOOKUP(2,1/('468滾動核查明細'!$A$2:$A$114=$A5),'468滾動核查明細'!$O$2:$O$114) | K5: =IF(J5>=90,"是","否") | L5: =IF(K5="是",ROUND(7*J5/365,1),0) | M5: 資料僅至3/26即中斷(共26天,未滿4週)，無法判定是否符合468規定；可能已離職或資料不完整，建議與HR核對。
A6: P0030 | B6: 周夏愉 | C6: =MINIFS(個人班表!$D$2:$D$785,個人班表!$B$2:$B$785,$A6) | D6: =MAXIFS(個人班表!$D$2:$D$785,個人班表!$B$2:$B$785,$A6) | E6: =DATEDIF(DATEVALUE(SUBSTITUTE($C6,"/","-")),DATEVALUE(SUBSTITUTE($D6,"/","-")),"d")+1 | F6: =SUMIFS('468滾動核查明細'!$M$2:$M$114,'468滾動核查明細'!$A$2:$A$114,$A6) | G6: =COUNTIFS('468滾動核查明細'!$A$2:$A$114,$A6,'468滾動核查明細'!$L$2:$L$114,"是") | H6: =MAXIFS('468滾動核查明細'!$O$2:$O$114,'468滾動核查明細'!$A$2:$A$114,$A6) | I6: =LOOKUP(2,1/('468滾動核查明細'!$A$2:$A$114=$A6),'468滾動核查明細'!$L$2:$L$114) | J6: =LOOKUP(2,1/('468滾動核查明細'!$A$2:$A$114=$A6),'468滾動核查明細'!$O$2:$O$114) | K6: =IF(J6>=90,"是","否") | L6: =IF(K6="是",ROUND(7*J6/365,1),0)
A7: P0031 | B7: 梁綽恩 | C7: =MINIFS(個人班表!$D$2:$D$785,個人班表!$B$2:$B$785,$A7) | D7: =MAXIFS(個人班表!$D$2:$D$785,個人班表!$B$2:$B$785,$A7) | E7: =DATEDIF(DATEVALUE(SUBSTITUTE($C7,"/","-")),DATEVALUE(SUBSTITUTE($D7,"/","-")),"d")+1 | F7: =SUMIFS('468滾動核查明細'!$M$2:$M$114,'468滾動核查明細'!$A$2:$A$114,$A7) | G7: =COUNTIFS('468滾動核查明細'!$A$2:$A$114,$A7,'468滾動核查明細'!$L$2:$L$114,"是") | H7: =MAXIFS('468滾動核查明細'!$O$2:$O$114,'468滾動核查明細'!$A$2:$A$114,$A7) | I7: =LOOKUP(2,1/('468滾動核查明細'!$A$2:$A$114=$A7),'468滾動核查明細'!$L$2:$L$114) | J7: =LOOKUP(2,1/('468滾動核查明細'!$A$2:$A$114=$A7),'468滾動核查明細'!$O$2:$O$114) | K7: =IF(J7>=90,"是","否") | L7: =IF(K7="是",ROUND(7*J7/365,1),0)

Sheet 468滾動核查明細
A1: 工號 | B1: 姓名 | C1: 週次 | D1: 週起始日 | E1: 週結束日 | F1: 是否為資料末週(未滿7天) | G1: 該週工時合計(小時) | H1: 單週達17小時 | I1: 本週+前3週合計(小時) | J1: 4週合計達68小時 | K1: 是否已受僱滿4週 | L1: 是否符合連續性合約(468規定) | M1: 本週實際計入天數 | N1: 員工資料最後日期(輔助) | O1: 本連續期累計天數(遇中斷歸零)
A2: P0026 | B2: 李芷彤 | C2: 1 | D2: 2026/03/01 | E2: 2026/03/07 | F2: 否 | G2: =SUMIFS(個人班表!$I$2:$I$784,個人班表!$B$2:$B$784,$A2,個人班表!$D$2:$D$784,">="&$D2,個人班表!$D$2:$D$784,"<="&$E2) | H2: =IF(G2>=17,"是","否") | I2: =SUM(G2:G2) | J2: =IF(I2>=68,"是","否") | K2: =IF(C2>=4,"是","否") | L2: =IF(AND(K2="是",OR(H2="是",J2="是")),"是","否") | M2: =IF(L2="是",MIN(7,DATEDIF(DATEVALUE(SUBSTITUTE($D2,"/","-")),MIN(DATEVALUE(SUBSTITUTE($E2,"/","-")),DATEVALUE(SUBSTITUTE($N2,"/","-"))),"d")+1),0) | N2: =MAXIFS(個人班表!$D$2:$D$784,個人班表!$B$2:$B$784,$A2) | O2: =IF(L2<>"是",0,M2)
A3: P0026 | B3: 李芷彤 | C3: 2 | D3: 2026/03/08 | E3: 2026/03/14 | F3: 否 | G3: =SUMIFS(個人班表!$I$2:$I$784,個人班表!$B$2:$B$784,$A3,個人班表!$D$2:$D$784,">="&$D3,個人班表!$D$2:$D$784,"<="&$E3) | H3: =IF(G3>=17,"是","否") | I3: =SUM(G2:G3) | J3: =IF(I3>=68,"是","否") | K3: =IF(C3>=4,"是","否") | L3: =IF(AND(K3="是",OR(H3="是",J3="是")),"是","否") | M3: =IF(L3="是",MIN(7,DATEDIF(DATEVALUE(SUBSTITUTE($D3,"/","-")),MIN(DATEVALUE(SUBSTITUTE($E3,"/","-")),DATEVALUE(SUBSTITUTE($N3,"/","-"))),"d")+1),0) | N3: =MAXIFS(個人班表!$D$2:$D$784,個人班表!$B$2:$B$784,$A3) | O3: =IF(L3<>"是",0,IF(AND($A3=$A2,$L2="是"),O2+M3,M3))
A4: P0026 | B4: 李芷彤 | C4: 3 | D4: 2026/03/15 | E4: 2026/03/21 | F4: 否 | G4: =SUMIFS(個人班表!$I$2:$I$784,個人班表!$B$2:$B$784,$A4,個人班表!$D$2:$D$784,">="&$D4,個人班表!$D$2:$D$784,"<="&$E4) | H4: =IF(G4>=17,"是","否") | I4: =SUM(G2:G4) | J4: =IF(I4>=68,"是","否") | K4: =IF(C4>=4,"是","否") | L4: =IF(AND(K4="是",OR(H4="是",J4="是")),"是","否") | M4: =IF(L4="是",MIN(7,DATEDIF(DATEVALUE(SUBSTITUTE($D4,"/","-")),MIN(DATEVALUE(SUBSTITUTE($E4,"/","-")),DATEVALUE(SUBSTITUTE($N4,"/","-"))),"d")+1),0) | N4: =MAXIFS(個人班表!$D$2:$D$784,個人班表!$B$2:$B$784,$A4) | O4: =IF(L4<>"是",0,IF(AND($A4=$A3,$L3="是"),O3+M4,M4))
A5: P0026 | B5: 李芷彤 | C5: 4 | D5: 2026/03/22 | E5: 2026/03/28 | F5: 否 | G5: =SUMIFS(個人班表!$I$2:$I$784,個人班表!$B$2:$B$784,$A5,個人班表!$D$2:$D$784,">="&$D5,個人班表!$D$2:$D$784,"<="&$E5) | H5: =IF(G5>=17,"是","否") | I5: =SUM(G2:G5) | J5: =IF(I5>=68,"是","否") | K5: =IF(C5>=4,"是","否") | L5: =IF(AND(K5="是",OR(H5="是",J5="是")),"是","否") | M5: =IF(L5="是",MIN(7,DATEDIF(DATEVALUE(SUBSTITUTE($D5,"/","-")),MIN(DATEVALUE(SUBSTITUTE($E5,"/","-")),DATEVALUE(SUBSTITUTE($N5,"/","-"))),"d")+1),0) | N5: =MAXIFS(個人班表!$D$2:$D$784,個人班表!$B$2:$B$784,$A5) | O5: =IF(L5<>"是",0,IF(AND($A5=$A4,$L4="是"),O4+M5,M5))
A6: P0026 | B6: 李芷彤 | C6: 5 | D6: 2026/03/29 | E6: 2026/04/04 | F6: 否 | G6: =SUMIFS(個人班表!$I$2:$I$784,個人班表!$B$2:$B$784,$A6,個人班表!$D$2:$D$784,">="&$D6,個人班表!$D$2:$D$784,"<="&$E6) | H6: =IF(G6>=17,"是","否") | I6: =SUM(G3:G6) | J6: =IF(I6>=68,"是","否") | K6: =IF(C6>=4,"是","否") | L6: =IF(AND(K6="是",OR(H6="是",J6="是")),"是","否") | M6: =IF(L6="是",MIN(7,DATEDIF(DATEVALUE(SUBSTITUTE($D6,"/","-")),MIN(DATEVALUE(SUBSTITUTE($E6,"/","-")),DATEVALUE(SUBSTITUTE($N6,"/","-"))),"d")+1),0) | N6: =MAXIFS(個人班表!$D$2:$D$784,個人班表!$B$2:$B$784,$A6) | O6: =IF(L6<>"是",0,IF(AND($A6=$A5,$L5="是"),O5+M6,M6))
A7: P0026 | B7: 李芷彤 | C7: 6 | D7: 2026/04/05 | E7: 2026/04/11 | F7: 否 | G7: =SUMIFS(個人班表!$I$2:$I$784,個人班表!$B$2:$B$784,$A7,個人班表!$D$2:$D$784,">="&$D7,個人班表!$D$2:$D$784,"<="&$E7) | H7: =IF(G7>=17,"是","否") | I7: =SUM(G4:G7) | J7: =IF(I7>=68,"是","否") | K7: =IF(C7>=4,"是","否") | L7: =IF(AND(K7="是",OR(H7="是",J7="是")),"是","否") | M7: =IF(L7="是",MIN(7,DATEDIF(DATEVALUE(SUBSTITUTE($D7,"/","-")),MIN(DATEVALUE(SUBSTITUTE($E7,"/","-")),DATEVALUE(SUBSTITUTE($N7,"/","-"))),"d")+1),0) | N7: =MAXIFS(個人班表!$D$2:$D$784,個人班表!$B$2:$B$784,$A7) | O7: =IF(L7<>"是",0,IF(AND($A7=$A6,$L6="是"),O6+M7,M7))
A8: P0026 | B8: 李芷彤 | C8: 7 | D8: 2026/04/12 | E8: 2026/04/18 | F8: 否 | G8: =SUMIFS(個人班表!$I$2:$I$784,個人班表!$B$2:$B$784,$A8,個人班表!$D$2:$D$784,">="&$D8,個人班表!$D$2:$D$784,"<="&$E8) | H8: =IF(G8>=17,"是","否") | I8: =SUM(G5:G8) | J8: =IF(I8>=68,"是","否") | K8: =IF(C8>=4,"是","否") | L8: =IF(AND(K8="是",OR(H8="是",J8="是")),"是","否") | M8: =IF(L8="是",MIN(7,DATEDIF(DATEVALUE(SUBSTITUTE($D8,"/","-")),MIN(DATEVALUE(SUBSTITUTE($E8,"/","-")),DATEVALUE(SUBSTITUTE($N8,"/","-"))),"d")+1),0) | N8: =MAXIFS(個人班表!$D$2:$D$784,個人班表!$B$2:$B$784,$A8) | O8: =IF(L8<>"是",0,IF(AND($A8=$A7,$L7="是"),O7+M8,M8))
A9: P0026 | B9: 李芷彤 | C9: 8 | D9: 2026/04/19 | E9: 2026/04/25 | F9: 否 | G9: =SUMIFS(個人班表!$I$2:$I$784,個人班表!$B$2:$B$784,$A9,個人班表!$D$2:$D$784,">="&$D9,個人班表!$D$2:$D$784,"<="&$E9) | H9: =IF(G9>=17,"是","否") | I9: =SUM(G6:G9) | J9: =IF(I9>=68,"是","否") | K9: =IF(C9>=4,"是","否") | L9: =IF(AND(K9="是",OR(H9="是",J9="是")),"是","否") | M9: =IF(L9="是",MIN(7,DATEDIF(DATEVALUE(SUBSTITUTE($D9,"/","-")),MIN(DATEVALUE(SUBSTITUTE($E9,"/","-")),DATEVALUE(SUBSTITUTE($N9,"/","-"))),"d")+1),0) | N9: =MAXIFS(個人班表!$D$2:$D$784,個人班表!$B$2:$B$784,$A9) | O9: =IF(L9<>"是",0,IF(AND($A9=$A8,$L8="是"),O8+M9,M9))
A10: P0026 | B10: 李芷彤 | C10: 9 | D10: 2026/04/26 | E10: 2026/05/02 | F10: 否 | G10: =SUMIFS(個人班表!$I$2:$I$784,個人班表!$B$2:$B$784,$A10,個人班表!$D$2:$D$784,">="&$D10,個人班表!$D$2:$D$784,"<="&$E10) | H10: =IF(G10>=17,"是","否") | I10: =SUM(G7:G10) | J10: =IF(I10>=68,"是","否") | K10: =IF(C10>=4,"是","否") | L10: =IF(AND(K10="是",OR(H10="是",J10="是")),"是","否") | M10: =IF(L10="是",MIN(7,DATEDIF(DATEVALUE(SUBSTITUTE($D10,"/","-")),MIN(DATEVALUE(SUBSTITUTE($E10,"/","-")),DATEVALUE(SUBSTITUTE($N10,"/","-"))),"d")+1),0) | N10: =MAXIFS(個人班表!$D$2:$D$784,個人班表!$B$2:$B$784,$A10) | O10: =IF(L10<>"是",0,IF(AND($A10=$A9,$L9="是"),O9+M10,M10))
A11: P0026 | B11: 李芷彤 | C11: 10 | D11: 2026/05/03 | E11: 2026/05/09 | F11: 否 | G11: =SUMIFS(個人班表!$I$2:$I$784,個人班表!$B$2:$B$784,$A11,個人班表!$D$2:$D$784,">="&$D11,個人班表!$D$2:$D$784,"<="&$E11) | H11: =IF(G11>=17,"是","否") | I11: =SUM(G8:G11) | J11: =IF(I11>=68,"是","否") | K11: =IF(C11>=4,"是","否") | L11: =IF(AND(K11="是",OR(H11="是",J11="是")),"是","否") | M11: =IF(L11="是",MIN(7,DATEDIF(DATEVALUE(SUBSTITUTE($D11,"/","-")),MIN(DATEVALUE(SUBSTITUTE($E11,"/","-")),DATEVALUE(SUBSTITUTE($N11,"/","-"))),"d")+1),0) | N11: =MAXIFS(個人班表!$D$2:$D$784,個人班表!$B$2:$B$784,$A11) | O11: =IF(L11<>"是",0,IF(AND($A11=$A10,$L10="是"),O10+M11,M11))
A12: P0026 | B12: 李芷彤 | C12: 11 | D12: 2026/05/10 | E12: 2026/05/16 | F12: 否 | G12: =SUMIFS(個人班表!$I$2:$I$784,個人班表!$B$2:$B$784,$A12,個人班表!$D$2:$D$784,">="&$D12,個人班表!$D$2:$D$784,"<="&$E12) | H12: =IF(G12>=17,"是","否") | I12: =SUM(G9:G12) | J12: =IF(I12>=68,"是","否") | K12: =IF(C12>=4,"是","否") | L12: =IF(AND(K12="是",OR(H12="是",J12="是")),"是","否") | M12: =IF(L12="是",MIN(7,DATEDIF(DATEVALUE(SUBSTITUTE($D12,"/","-")),MIN(DATEVALUE(SUBSTITUTE($E12,"/","-")),DATEVALUE(SUBSTITUTE($N12,"/","-"))),"d")+1),0) | N12: =MAXIFS(個人班表!$D$2:$D$784,個人班表!$B$2:$B$784,$A12) | O12: =IF(L12<>"是",0,IF(AND($A12=$A11,$L11="是"),O11+M12,M12))
A13: P0026 | B13: 李芷彤 | C13: 12 | D13: 2026/05/17 | E13: 2026/05/23 | F13: 否 | G13: =SUMIFS(個人班表!$I$2:$I$784,個人班表!$B$2:$B$784,$A13,個人班表!$D$2:$D$784,">="&$D13,個人班表!$D$2:$D$784,"<="&$E13) | H13: =IF(G13>=17,"是","否") | I13: =SUM(G10:G13) | J13: =IF(I13>=68,"是","否") | K13: =IF(C13>=4,"是","否") | L13: =IF(AND(K13="是",OR(H13="是",J13="是")),"是","否") | M13: =IF(L13="是",MIN(7,DATEDIF(DATEVALUE(SUBSTITUTE($D13,"/","-")),MIN(DATEVALUE(SUBSTITUTE($E13,"/","-")),DATEVALUE(SUBSTITUTE($N13,"/","-"))),"d")+1),0) | N13: =MAXIFS(個人班表!$D$2:$D$784,個人班表!$B$2:$B$784,$A13) | O13: =IF(L13<>"是",0,IF(AND($A13=$A12,$L12="是"),O12+M13,M13))
A14: P0026 | B14: 李芷彤 | C14: 13 | D14: 2026/05/24 | E14: 2026/05/30 | F14: 否 | G14: =SUMIFS(個人班表!$I$2:$I$784,個人班表!$B$2:$B$784,$A14,個人班表!$D$2:$D$784,">="&$D14,個人班表!$D$2:$D$784,"<="&$E14) | H14: =IF(G14>=17,"是","否") | I14: =SUM(G11:G14) | J14: =IF(I14>=68,"是","否") | K14: =IF(C14>=4,"是","否") | L14: =IF(AND(K14="是",OR(H14="是",J14="是")),"是","否") | M14: =IF(L14="是",MIN(7,DATEDIF(DATEVALUE(SUBSTITUTE($D14,"/","-")),MIN(DATEVALUE(SUBSTITUTE($E14,"/","-")),DATEVALUE(SUBSTITUTE($N14,"/","-"))),"d")+1),0) | N14: =MAXIFS(個人班表!$D$2:$D$784,個人班表!$B$2:$B$784,$A14) | O14: =IF(L14<>"是",0,IF(AND($A14=$A13,$L13="是"),O13+M14,M14))
A15: P0026 | B15: 李芷彤 | C15: 14 | D15: 2026/05/31 | E15: 2026/06/06 | F15: 否 | G15: =SUMIFS(個人班表!$I$2:$I$784,個人班表!$B$2:$B$784,$A15,個人班表!$D$2:$D$784,">="&$D15,個人班表!$D$2:$D$784,"<="&$E15) | H15: =IF(G15>=17,"是","否") | I15: =SUM(G12:G15) | J15: =IF(I15>=68,"是","否") | K15: =IF(C15>=4,"是","否") | L15: =IF(AND(K15="是",OR(H15="是",J15="是")),"是","否") | M15: =IF(L15="是",MIN(7,DATEDIF(DATEVALUE(SUBSTITUTE($D15,"/","-")),MIN(DATEVALUE(SUBSTITUTE($E15,"/","-")),DATEVALUE(SUBSTITUTE($N15,"/","-"))),"d")+1),0) | N15: =MAXIFS(個人班表!$D$2:$D$784,個人班表!$B$2:$B$784,$A15) | O15: =IF(L15<>"是",0,IF(AND($A15=$A14,$L14="是"),O14+M15,M15))
A16: P0026 | B16: 李芷彤 | C16: 15 | D16: 2026/06/07 | E16: 2026/06/13 | F16: 否 | G16: =SUMIFS(個人班表!$I$2:$I$784,個人班表!$B$2:$B$784,$A16,個人班表!$D$2:$D$784,">="&$D16,個人班表!$D$2:$D$784,"<="&$E16) | H16: =IF(G16>=17,"是","否") | I16: =SUM(G13:G16) | J16: =IF(I16>=68,"是","否") | K16: =IF(C16>=4,"是","否") | L16: =IF(AND(K16="是",OR(H16="是",J16="是")),"是","否") | M16: =IF(L16="是",MIN(7,DATEDIF(DATEVALUE(SUBSTITUTE($D16,"/","-")),MIN(DATEVALUE(SUBSTITUTE($E16,"/","-")),DATEVALUE(SUBSTITUTE($N16,"/","-"))),"d")+1),0) | N16: =MAXIFS(個人班表!$D$2:$D$784,個人班表!$B$2:$B$784,$A16) | O16: =IF(L16<>"是",0,IF(AND($A16=$A15,$L15="是"),O15+M16,M16))
... A23: P0026 | B23: 李芷彤 | C23: 22 | D23: 2026/07/26 | E23: 2026/08/01 | F23: 是 | G23: =SUMIFS(個人班表!$I$2:$I$784,個人班表!$B$2:$B$784,$A23,個人班表!$D$2:$D$784,">="&$D23,個人班表!$D$2:$D$784,"<="&$E23) | H23: =IF(G23>=17,"是","否") | I23: =SUM(G20:G23) | J23: =IF(I23>=68,"是","否") | K23: =IF(C23>=4,"是","否") | L23: =IF(AND(K23="是",OR(H23="是",J23="是")),"是","否") | M23: =IF(L23="是",MIN(7,DATEDIF(DATEVALUE(SUBSTITUTE($D23,"/","-")),MIN(DATEVALUE(SUBSTITUTE($E23,"/","-")),DATEVALUE(SUBSTITUTE($N23,"/","-"))),"d")+1),0) | N23: =MAXIFS(個人班表!$D$2:$D$784,個人班表!$B$2:$B$784,$A23) | O23: =IF(L23<>"是",0,IF(AND($A23=$A22,$L22="是"),O22+M23,M23))
A24: P0027 | B24: 陳詩祺 | C24: 1 | D24: 2026/03/01 | E24: 2026/03/07 | F24: 否 | G24: =SUMIFS(個人班表!$I$2:$I$784,個人班表!$B$2:$B$784,$A24,個人班表!$D$2:$D$784,">="&$D24,個人班表!$D$2:$D$784,"<="&$E24) | H24: =IF(G24>=17,"是","否") | I24: =SUM(G24:G24) | J24: =IF(I24>=68,"是","否") | K24: =IF(C24>=4,"是","否") | L24: =IF(AND(K24="是",OR(H24="是",J24="是")),"是","否") | M24: =IF(L24="是",MIN(7,DATEDIF(DATEVALUE(SUBSTITUTE($D24,"/","-")),MIN(DATEVALUE(SUBSTITUTE($E24,"/","-")),DATEVALUE(SUBSTITUTE($N24,"/","-"))),"d")+1),0) | N24: =MAXIFS(個人班表!$D$2:$D$784,個人班表!$B$2:$B$784,$A24) | O24: =IF(L24<>"是",0,M24)
A25: P0027 | B25: 陳詩祺 | C25: 2 | D25: 2026/03/08 | E25: 2026/03/14 | F25: 否 | G25: =SUMIFS(個人班表!$I$2:$I$784,個人班表!$B$2:$B$784,$A25,個人班表!$D$2:$D$784,">="&$D25,個人班表!$D$2:$D$784,"<="&$E25) | H25: =IF(G25>=17,"是","否") | I25: =SUM(G24:G25) | J25: =IF(I25>=68,"是","否") | K25: =IF(C25>=4,"是","否") | L25: =IF(AND(K25="是",OR(H25="是",J25="是")),"是","否") | M25: =IF(L25="是",MIN(7,DATEDIF(DATEVALUE(SUBSTITUTE($D25,"/","-")),MIN(DATEVALUE(SUBSTITUTE($E25,"/","-")),DATEVALUE(SUBSTITUTE($N25,"/","-"))),"d")+1),0) | N25: =MAXIFS(個人班表!$D$2:$D$784,個人班表!$B$2:$B$784,$A25) | O25: =IF(L25<>"是",0,IF(AND($A25=$A24,$L24="是"),O24+M25,M25))
A26: P0027 | B26: 陳詩祺 | C26: 3 | D26: 2026/03/15 | E26: 2026/03/21 | F26: 否 | G26: =SUMIFS(個人班表!$I$2:$I$784,個人班表!$B$2:$B$784,$A26,個人班表!$D$2:$D$784,">="&$D26,個人班表!$D$2:$D$784,"<="&$E26) | H26: =IF(G26>=17,"是","否") | I26: =SUM(G24:G26) | J26: =IF(I26>=68,"是","否") | K26: =IF(C26>=4,"是","否") | L26: =IF(AND(K26="是",OR(H26="是",J26="是")),"是","否") | M26: =IF(L26="是",MIN(7,DATEDIF(DATEVALUE(SUBSTITUTE($D26,"/","-")),MIN(DATEVALUE(SUBSTITUTE($E26,"/","-")),DATEVALUE(SUBSTITUTE($N26,"/","-"))),"d")+1),0) | N26: =MAXIFS(個人班表!$D$2:$D$784,個人班表!$B$2:$B$784,$A26) | O26: =IF(L26<>"是",0,IF(AND($A26=$A25,$L25="是"),O25+M26,M26))
A27: P0027 | B27: 陳詩祺 | C27: 4 | D27: 2026/03/22 | E27: 2026/03/28 | F27: 否 | G27: =SUMIFS(個人班表!$I$2:$I$784,個人班表!$B$2:$B$784,$A27,個人班表!$D$2:$D$784,">="&$D27,個人班表!$D$2:$D$784,"<="&$E27) | H27: =IF(G27>=17,"是","否") | I27: =SUM(G24:G27) | J27: =IF(I27>=68,"是","否") | K27: =IF(C27>=4,"是","否") | L27: =IF(AND(K27="是",OR(H27="是",J27="是")),"是","否") | M27: =IF(L27="是",MIN(7,DATEDIF(DATEVALUE(SUBSTITUTE($D27,"/","-")),MIN(DATEVALUE(SUBSTITUTE($E27,"/","-")),DATEVALUE(SUBSTITUTE($N27,"/","-"))),"d")+1),0) | N27: =MAXIFS(個人班表!$D$2:$D$784,個人班表!$B$2:$B$784,$A27) | O27: =IF(L27<>"是",0,IF(AND($A27=$A26,$L26="是"),O26+M27,M27))
A28: P0027 | B28: 陳詩祺 | C28: 5 | D28: 2026/03/29 | E28: 2026/04/04 | F28: 否 | G28: =SUMIFS(個人班表!$I$2:$I$784,個人班表!$B$2:$B$784,$A28,個人班表!$D$2:$D$784,">="&$D28,個人班表!$D$2:$D$784,"<="&$E28) | H28: =IF(G28>=17,"是","否") | I28: =SUM(G25:G28) | J28: =IF(I28>=68,"是","否") | K28: =IF(C28>=4,"是","否") | L28: =IF(AND(K28="是",OR(H28="是",J28="是")),"是","否") | M28: =IF(L28="是",MIN(7,DATEDIF(DATEVALUE(SUBSTITUTE($D28,"/","-")),MIN(DATEVALUE(SUBSTITUTE($E28,"/","-")),DATEVALUE(SUBSTITUTE($N28,"/","-"))),"d")+1),0) | N28: =MAXIFS(個人班表!$D$2:$D$784,個人班表!$B$2:$B$784,$A28) | O28: =IF(L28<>"是",0,IF(AND($A28=$A27,$L27="是"),O27+M28,M28))
A29: P0027 | B29: 陳詩祺 | C29: 6 | D29: 2026/04/05 | E29: 2026/04/11 | F29: 否 | G29: =SUMIFS(個人班表!$I$2:$I$784,個人班表!$B$2:$B$784,$A29,個人班表!$D$2:$D$784,">="&$D29,個人班表!$D$2:$D$784,"<="&$E29) | H29: =IF(G29>=17,"是","否") | I29: =SUM(G26:G29) | J29: =IF(I29>=68,"是","否") | K29: =IF(C29>=4,"是","否") | L29: =IF(AND(K29="是",OR(H29="是",J29="是")),"是","否") | M29: =IF(L29="是",MIN(7,DATEDIF(DATEVALUE(SUBSTITUTE($D29,"/","-")),MIN(DATEVALUE(SUBSTITUTE($E29,"/","-")),DATEVALUE(SUBSTITUTE($N29,"/","-"))),"d")+1),0) | N29: =MAXIFS(個人班表!$D$2:$D$784,個人班表!$B$2:$B$784,$A29) | O29: =IF(L29<>"是",0,IF(AND($A29=$A28,$L28="是"),O28+M29,M29))
A30: P0027 | B30: 陳詩祺 | C30: 7 | D30: 2026/04/12 | E30: 2026/04/18 | F30: 否 | G30: =SUMIFS(個人班表!$I$2:$I$784,個人班表!$B$2:$B$784,$A30,個人班表!$D$2:$D$784,">="&$D30,個人班表!$D$2:$D$784,"<="&$E30) | H30: =IF(G30>=17,"是","否") | I30: =SUM(G27:G30) | J30: =IF(I30>=68,"是","否") | K30: =IF(C30>=4,"是","否") | L30: =IF(AND(K30="是",OR(H30="是",J30="是")),"是","否") | M30: =IF(L30="是",MIN(7,DATEDIF(DATEVALUE(SUBSTITUTE($D30,"/","-")),MIN(DATEVALUE(SUBSTITUTE($E30,"/","-")),DATEVALUE(SUBSTITUTE($N30,"/","-"))),"d")+1),0) | N30: =MAXIFS(個人班表!$D$2:$D$784,個人班表!$B$2:$B$784,$A30) | O30: =IF(L30<>"是",0,IF(AND($A30=$A29,$L29="是"),O29+M30,M30))
A31: P0027 | B31: 陳詩祺 | C31: 8 | D31: 2026/04/19 | E31: 2026/04/25 | F31: 否 | G31: =SUMIFS(個人班表!$I$2:$I$784,個人班表!$B$2:$B$784,$A31,個人班表!$D$2:$D$784,">="&$D31,個人班表!$D$2:$D$784,"<="&$E31) | H31: =IF(G31>=17,"是","否") | I31: =SUM(G28:G31) | J31: =IF(I31>=68,"是","否") | K31: =IF(C31>=4,"是","否") | L31: =IF(AND(K31="是",OR(H31="是",J31="是")),"是","否") | M31: =IF(L31="是",MIN(7,DATEDIF(DATEVALUE(SUBSTITUTE($D31,"/","-")),MIN(DATEVALUE(SUBSTITUTE($E31,"/","-")),DATEVALUE(SUBSTITUTE($N31,"/","-"))),"d")+1),0) | N31: =MAXIFS(個人班表!$D$2:$D$784,個人班表!$B$2:$B$784,$A31) | O31: =IF(L31<>"是",0,IF(AND($A31=$A30,$L30="是"),O30+M31,M31))
A32: P0027 | B32: 陳詩祺 | C32: 9 | D32: 2026/04/26 | E32: 2026/05/02 | F32: 否 | G32: =SUMIFS(個人班表!$I$2:$I$784,個人班表!$B$2:$B$784,$A32,個人班表!$D$2:$D$784,">="&$D32,個人班表!$D$2:$D$784,"<="&$E32) | H32: =IF(G32>=17,"是","否") | I32: =SUM(G29:G32) | J32: =IF(I32>=68,"是","否") | K32: =IF(C32>=4,"是","否") | L32: =IF(AND(K32="是",OR(H32="是",J32="是")),"是","否") | M32: =IF(L32="是",MIN(7,DATEDIF(DATEVALUE(SUBSTITUTE($D32,"/","-")),MIN(DATEVALUE(SUBSTITUTE($E32,"/","-")),DATEVALUE(SUBSTITUTE($N32,"/","-"))),"d")+1),0) | N32: =MAXIFS(個人班表!$D$2:$D$784,個人班表!$B$2:$B$784,$A32) | O32: =IF(L32<>"是",0,IF(AND($A32=$A31,$L31="是"),O31+M32,M32))
A33: P0027 | B33: 陳詩祺 | C33: 10 | D33: 2026/05/03 | E33: 2026/05/09 | F33: 否 | G33: =SUMIFS(個人班表!$I$2:$I$784,個人班表!$B$2:$B$784,$A33,個人班表!$D$2:$D$784,">="&$D33,個人班表!$D$2:$D$784,"<="&$E33) | H33: =IF(G33>=17,"是","否") | I33: =SUM(G30:G33) | J33: =IF(I33>=68,"是","否") | K33: =IF(C33>=4,"是","否") | L33: =IF(AND(K33="是",OR(H33="是",J33="是")),"是","否") | M33: =IF(L33="是",MIN(7,DATEDIF(DATEVALUE(SUBSTITUTE($D33,"/","-")),MIN(DATEVALUE(SUBSTITUTE($E33,"/","-")),DATEVALUE(SUBSTITUTE($N33,"/","-"))),"d")+1),0) | N33: =MAXIFS(個人班表!$D$2:$D$784,個人班表!$B$2:$B$784,$A33) | O33: =IF(L33<>"是",0,IF(AND($A33=$A32,$L32="是"),O32+M33,M33))
A34: P0027 | B34: 陳詩祺 | C34: 11 | D34: 2026/05/10 | E34: 2026/05/16 | F34: 否 | G34: =SUMIFS(個人班表!$I$2:$I$784,個人班表!$B$2:$B$784,$A34,個人班表!$D$2:$D$784,">="&$D34,個人班表!$D$2:$D$784,"<="&$E34) | H34: =IF(G34>=17,"是","否") | I34: =SUM(G31:G34) | J34: =IF(I34>=68,"是","否") | K34: =IF(C34>=4,"是","否") | L34: =IF(AND(K34="是",OR(H34="是",J34="是")),"是","否") | M34: =IF(L34="是",MIN(7,DATEDIF(DATEVALUE(SUBSTITUTE($D34,"/","-")),MIN(DATEVALUE(SUBSTITUTE($E34,"/","-")),DATEVALUE(SUBSTITUTE($N34,"/","-"))),"d")+1),0) | N34: =MAXIFS(個人班表!$D$2:$D$784,個人班表!$B$2:$B$784,$A34) | O34: =IF(L34<>"是",0,IF(AND($A34=$A33,$L33="是"),O33+M34,M34))
A35: P0027 | B35: 陳詩祺 | C35: 12 | D35: 2026/05/17 | E35: 2026/05/23 | F35: 否 | G35: =SUMIFS(個人班表!$I$2:$I$784,個人班表!$B$2:$B$784,$A35,個人班表!$D$2:$D$784,">="&$D35,個人班表!$D$2:$D$784,"<="&$E35) | H35: =IF(G35>=17,"是","否") | I35: =SUM(G32:G35) | J35: =IF(I35>=68,"是","否") | K35: =IF(C35>=4,"是","否") | L35: =IF(AND(K35="是",OR(H35="是",J35="是")),"是","否") | M35: =IF(L35="是",MIN(7,DATEDIF(DATEVALUE(SUBSTITUTE($D35,"/","-")),MIN(DATEVALUE(SUBSTITUTE($E35,"/","-")),DATEVALUE(SUBSTITUTE($N35,"/","-"))),"d")+1),0) | N35: =MAXIFS(個人班表!$D$2:$D$784,個人班表!$B$2:$B$784,$A35) | O35: =IF(L35<>"是",0,IF(AND($A35=$A34,$L34="是"),O34+M35,M35))
A36: P0027 | B36: 陳詩祺 | C36: 13 | D36: 2026/05/24 | E36: 2026/05/30 | F36: 否 | G36: =SUMIFS(個人班表!$I$2:$I$784,個人班表!$B$2:$B$784,$A36,個人班表!$D$2:$D$784,">="&$D36,個人班表!$D$2:$D$784,"<="&$E36) | H36: =IF(G36>=17,"是","否") | I36: =SUM(G33:G36) | J36: =IF(I36>=68,"是","否") | K36: =IF(C36>=4,"是","否") | L36: =IF(AND(K36="是",OR(H36="是",J36="是")),"是","否") | M36: =IF(L36="是",MIN(7,DATEDIF(DATEVALUE(SUBSTITUTE($D36,"/","-")),MIN(DATEVALUE(SUBSTITUTE($E36,"/","-")),DATEVALUE(SUBSTITUTE($N36,"/","-"))),"d")+1),0) | N36: =MAXIFS(個人班表!$D$2:$D$784,個人班表!$B$2:$B$784,$A36) | O36: =IF(L36<>"是",0,IF(AND($A36=$A35,$L35="是"),O35+M36,M36))
A37: P0027 | B37: 陳詩祺 | C37: 14 | D37: 2026/05/31 | E37: 2026/06/06 | F37: 否 | G37: =SUMIFS(個人班表!$I$2:$I$784,個人班表!$B$2:$B$784,$A37,個人班表!$D$2:$D$784,">="&$D37,個人班表!$D$2:$D$784,"<="&$E37) | H37: =IF(G37>=17,"是","否") | I37: =SUM(G34:G37) | J37: =IF(I37>=68,"是","否") | K37: =IF(C37>=4,"是","否") | L37: =IF(AND(K37="是",OR(H37="是",J37="是")),"是","否") | M37: =IF(L37="是",MIN(7,DATEDIF(DATEVALUE(SUBSTITUTE($D37,"/","-")),MIN(DATEVALUE(SUBSTITUTE($E37,"/","-")),DATEVALUE(SUBSTITUTE($N37,"/","-"))),"d")+1),0) | N37: =MAXIFS(個人班表!$D$2:$D$784,個人班表!$B$2:$B$784,$A37) | O37: =IF(L37<>"是",0,IF(AND($A37=$A36,$L36="是"),O36+M37,M37))
A38: P0027 | B38: 陳詩祺 | C38: 15 | D38: 2026/06/07 | E38: 2026/06/13 | F38: 否 | G38: =SUMIFS(個人班表!$I$2:$I$784,個人班表!$B$2:$B$784,$A38,個人班表!$D$2:$D$784,">="&$D38,個人班表!$D$2:$D$784,"<="&$E38) | H38: =IF(G38>=17,"是","否") | I38: =SUM(G35:G38) | J38: =IF(I38>=68,"是","否") | K38: =IF(C38>=4,"是","否") | L38: =IF(AND(K38="是",OR(H38="是",J38="是")),"是","否") | M38: =IF(L38="是",MIN(7,DATEDIF(DATEVALUE(SUBSTITUTE($D38,"/","-")),MIN(DATEVALUE(SUBSTITUTE($E38,"/","-")),DATEVALUE(SUBSTITUTE($N38,"/","-"))),"d")+1),0) | N38: =MAXIFS(個人班表!$D$2:$D$784,個人班表!$B$2:$B$784,$A38) | O38: =IF(L38<>"是",0,IF(AND($A38=$A37,$L37="是"),O37+M38,M38))
... A45: P0027 | B45: 陳詩祺 | C45: 22 | D45: 2026/07/26 | E45: 2026/08/01 | F45: 是 | G45: =SUMIFS(個人班表!$I$2:$I$784,個人班表!$B$2:$B$784,$A45,個人班表!$D$2:$D$784,">="&$D45,個人班表!$D$2:$D$784,"<="&$E45) | H45: =IF(G45>=17,"是","否") | I45: =SUM(G42:G45) | J45: =IF(I45>=68,"是","否") | K45: =IF(C45>=4,"是","否") | L45: =IF(AND(K45="是",OR(H45="是",J45="是")),"是","否") | M45: =IF(L45="是",MIN(7,DATEDIF(DATEVALUE(SUBSTITUTE($D45,"/","-")),MIN(DATEVALUE(SUBSTITUTE($E45,"/","-")),DATEVALUE(SUBSTITUTE($N45,"/","-"))),"d")+1),0) | N45: =MAXIFS(個人班表!$D$2:$D$784,個人班表!$B$2:$B$784,$A45) | O45: =IF(L45<>"是",0,IF(AND($A45=$A44,$L44="是"),O44+M45,M45))
A46: P0028 | B46: 盧天欣 | C46: 1 | D46: 2026/03/01 | E46: 2026/03/07 | F46: 否 | G46: =SUMIFS(個人班表!$I$2:$I$784,個人班表!$B$2:$B$784,$A46,個人班表!$D$2:$D$784,">="&$D46,個人班表!$D$2:$D$784,"<="&$E46) | H46: =IF(G46>=17,"是","否") | I46: =SUM(G46:G46) | J46: =IF(I46>=68,"是","否") | K46: =IF(C46>=4,"是","否") | L46: =IF(AND(K46="是",OR(H46="是",J46="是")),"是","否") | M46: =IF(L46="是",MIN(7,DATEDIF(DATEVALUE(SUBSTITUTE($D46,"/","-")),MIN(DATEVALUE(SUBSTITUTE($E46,"/","-")),DATEVALUE(SUBSTITUTE($N46,"/","-"))),"d")+1),0) | N46: =MAXIFS(個人班表!$D$2:$D$784,個人班表!$B$2:$B$784,$A46) | O46: =IF(L46<>"是",0,M46)
A47: P0028 | B47: 盧天欣 | C47: 2 | D47: 2026/03/08 | E47: 2026/03/14 | F47: 否 | G47: =SUMIFS(個人班表!$I$2:$I$784,個人班表!$B$2:$B$784,$A47,個人班表!$D$2:$D$784,">="&$D47,個人班表!$D$2:$D$784,"<="&$E47) | H47: =IF(G47>=17,"是","否") | I47: =SUM(G46:G47) | J47: =IF(I47>=68,"是","否") | K47: =IF(C47>=4,"是","否") | L47: =IF(AND(K47="是",OR(H47="是",J47="是")),"是","否") | M47: =IF(L47="是",MIN(7,DATEDIF(DATEVALUE(SUBSTITUTE($D47,"/","-")),MIN(DATEVALUE(SUBSTITUTE($E47,"/","-")),DATEVALUE(SUBSTITUTE($N47,"/","-"))),"d")+1),0) | N47: =MAXIFS(個人班表!$D$2:$D$784,個人班表!$B$2:$B$784,$A47) | O47: =IF(L47<>"是",0,IF(AND($A47=$A46,$L46="是"),O46+M47,M47))
A48: P0028 | B48: 盧天欣 | C48: 3 | D48: 2026/03/15 | E48: 2026/03/21 | F48: 否 | G48: =SUMIFS(個人班表!$I$2:$I$784,個人班表!$B$2:$B$784,$A48,個人班表!$D$2:$D$784,">="&$D48,個人班表!$D$2:$D$784,"<="&$E48) | H48: =IF(G48>=17,"是","否") | I48: =SUM(G46:G48) | J48: =IF(I48>=68,"是","否") | K48: =IF(C48>=4,"是","否") | L48: =IF(AND(K48="是",OR(H48="是",J48="是")),"是","否") | M48: =IF(L48="是",MIN(7,DATEDIF(DATEVALUE(SUBSTITUTE($D48,"/","-")),MIN(DATEVALUE(SUBSTITUTE($E48,"/","-")),DATEVALUE(SUBSTITUTE($N48,"/","-"))),"d")+1),0) | N48: =MAXIFS(個人班表!$D$2:$D$784,個人班表!$B$2:$B$784,$A48) | O48: =IF(L48<>"是",0,IF(AND($A48=$A47,$L47="是"),O47+M48,M48))
A49: P0028 | B49: 盧天欣 | C49: 4 | D49: 2026/03/22 | E49: 2026/03/28 | F49: 否 | G49: =SUMIFS(個人班表!$I$2:$I$784,個人班表!$B$2:$B$784,$A49,個人班表!$D$2:$D$784,">="&$D49,個人班表!$D$2:$D$784,"<="&$E49) | H49: =IF(G49>=17,"是","否") | I49: =SUM(G46:G49) | J49: =IF(I49>=68,"是","否") | K49: =IF(C49>=4,"是","否") | L49: =IF(AND(K49="是",OR(H49="是",J49="是")),"是","否") | M49: =IF(L49="是",MIN(7,DATEDIF(DATEVALUE(SUBSTITUTE($D49,"/","-")),MIN(DATEVALUE(SUBSTITUTE($E49,"/","-")),DATEVALUE(SUBSTITUTE($N49,"/","-"))),"d")+1),0) | N49: =MAXIFS(個人班表!$D$2:$D$784,個人班表!$B$2:$B$784,$A49) | O49: =IF(L49<>"是",0,IF(AND($A49=$A48,$L48="是"),O48+M49,M49))
A50: P0028 | B50: 盧天欣 | C50: 5 | D50: 2026/03/29 | E50: 2026/04/04 | F50: 否 | G50: =SUMIFS(個人班表!$I$2:$I$784,個人班表!$B$2:$B$784,$A50,個人班表!$D$2:$D$784,">="&$D50,個人班表!$D$2:$D$784,"<="&$E50) | H50: =IF(G50>=17,"是","否") | I50: =SUM(G47:G50) | J50: =IF(I50>=68,"是","否") | K50: =IF(C50>=4,"是","否") | L50: =IF(AND(K50="是",OR(H50="是",J50="是")),"是","否") | M50: =IF(L50="是",MIN(7,DATEDIF(DATEVALUE(SUBSTITUTE($D50,"/","-")),MIN(DATEVALUE(SUBSTITUTE($E50,"/","-")),DATEVALUE(SUBSTITUTE($N50,"/","-"))),"d")+1),0) | N50: =MAXIFS(個人班表!$D$2:$D$784,個人班表!$B$2:$B$784,$A50) | O50: =IF(L50<>"是",0,IF(AND($A50=$A49,$L49="是"),O49+M50,M50))
A51: P0028 | B51: 盧天欣 | C51: 6 | D51: 2026/04/05 | E51: 2026/04/11 | F51: 否 | G51: =SUMIFS(個人班表!$I$2:$I$784,個人班表!$B$2:$B$784,$A51,個人班表!$D$2:$D$784,">="&$D51,個人班表!$D$2:$D$784,"<="&$E51) | H51: =IF(G51>=17,"是","否") | I51: =SUM(G48:G51) | J51: =IF(I51>=68,"是","否") | K51: =IF(C51>=4,"是","否") | L51: =IF(AND(K51="是",OR(H51="是",J51="是")),"是","否") | M51: =IF(L51="是",MIN(7,DATEDIF(DATEVALUE(SUBSTITUTE($D51,"/","-")),MIN(DATEVALUE(SUBSTITUTE($E51,"/","-")),DATEVALUE(SUBSTITUTE($N51,"/","-"))),"d")+1),0) | N51: =MAXIFS(個人班表!$D$2:$D$784,個人班表!$B$2:$B$784,$A51) | O51: =IF(L51<>"是",0,IF(AND($A51=$A50,$L50="是"),O50+M51,M51))
A52: P0028 | B52: 盧天欣 | C52: 7 | D52: 2026/04/12 | E52: 2026/04/18 | F52: 否 | G52: =SUMIFS(個人班表!$I$2:$I$784,個人班表!$B$2:$B$784,$A52,個人班表!$D$2:$D$784,">="&$D52,個人班表!$D$2:$D$784,"<="&$E52) | H52: =IF(G52>=17,"是","否") | I52: =SUM(G49:G52) | J52: =IF(I52>=68,"是","否") | K52: =IF(C52>=4,"是","否") | L52: =IF(AND(K52="是",OR(H52="是",J52="是")),"是","否") | M52: =IF(L52="是",MIN(7,DATEDIF(DATEVALUE(SUBSTITUTE($D52,"/","-")),MIN(DATEVALUE(SUBSTITUTE($E52,"/","-")),DATEVALUE(SUBSTITUTE($N52,"/","-"))),"d")+1),0) | N52: =MAXIFS(個人班表!$D$2:$D$784,個人班表!$B$2:$B$784,$A52) | O52: =IF(L52<>"是",0,IF(AND($A52=$A51,$L51="是"),O51+M52,M52))
...

Sheet 個人班表
A1: 單位 | B1: 工號 | C1: 姓名 | D1: 日期 | E1: 狀態 | F1: 班次 | G1: 上班時間 | H1: 下班時間 | I1: 總計工時 | J1: 調整後上班時間 | K1: 調整後下班時間 | L1: 是否為彈性上下班
A2: 香港專櫃課 | B2: P0026 | C2: 李芷彤 | D2: 2026/03/01 | I2: 0
A3: 香港專櫃課 | B3: P0026 | C3: 李芷彤 | D3: 2026/03/02 | I3: 0
A4: 香港專櫃課 | B4: P0026 | C4: 李芷彤 | D4: 2026/03/03 | I4: 0
A5: 香港專櫃課 | B5: P0026 | C5: 李芷彤 | D5: 2026/03/04 | I5: 0
A6: 香港專櫃課 | B6: P0026 | C6: 李芷彤 | D6: 2026/03/05 | I6: 0
A7: 香港專櫃課 | B7: P0026 | C7: 李芷彤 | D7: 2026/03/06 | I7: 0
A8: 香港專櫃課 | B8: P0026 | C8: 李芷彤 | D8: 2026/03/07 | I8: 0
A9: 香港專櫃課 | B9: P0026 | C9: 李芷彤 | D9: 2026/03/08 | I9: 0
A10: 香港專櫃課 | B10: P0026 | C10: 李芷彤 | D10: 2026/03/09 | I10: 0
A11: 香港專櫃課 | B11: P0026 | C11: 李芷彤 | D11: 2026/03/10 | I11: 0
A12: 香港專櫃課 | B12: P0026 | C12: 李芷彤 | D12: 2026/03/11 | I12: 0
A13: 香港專櫃課 | B13: P0026 | C13: 李芷彤 | D13: 2026/03/12 | E13: 上班 | F13: 職前訓練 | G13: 18:00 | H13: 20:00 | I13: 2 | J13: 18:00 | K13: 20:00 | L13: 否
A14: 香港專櫃課 | B14: P0026 | C14: 李芷彤 | D14: 2026/03/13 | I14: 0
A15: 香港專櫃課 | B15: P0026 | C15: 李芷彤 | D15: 2026/03/14 | E15: 上班 | F15: 職前訓練 | G15: 19:00 | H15: 21:00 | I15: 2 | J15: 19:00 | K15: 21:00 | L15: 否
A16: 香港專櫃課 | B16: P0026 | C16: 李芷彤 | D16: 2026/03/15 | E16: 上班 | F16: 職前訓練 | G16: 18:00 | H16: 20:00 | I16: 2 | J16: 18:00 | K16: 20:00 | L16: 否
A17: 香港專櫃課 | B17: P0026 | C17: 李芷彤 | D17: 2026/03/16 | I17: 0
A18: 香港專櫃課 | B18: P0026 | C18: 李芷彤 | D18: 2026/03/17 | I18: 0
A19: 香港專櫃課 | B19: P0026 | C19: 李芷彤 | D19: 2026/03/18 | I19: 0
A20: 香港專櫃課 | B20: P0026 | C20: 李芷彤 | D20: 2026/03/19 | E20: 月休 | I20: 0
A21: 香港專櫃課 | B21: P0026 | C21: 李芷彤 | D21: 2026/03/20 | E21: 月休 | I21: 0
A22: 香港專櫃課 | B22: P0026 | C22: 李芷彤 | D22: 2026/03/21 | E22: 月休 | I22: 0
A23: 香港專櫃課 | B23: P0026 | C23: 李芷彤 | D23: 2026/03/22 | E23: 月休 | I23: 0
A24: 香港專櫃課 | B24: P0026 | C24: 李芷彤 | D24: 2026/03/23 | E24: 上班 | F24: 香港晚班 | G24: 16:00 | H24: 21:00 | I24: 5 | J24: 16:00 | K24: 21:00 | L24: 否
A25: 香港專櫃課 | B25: P0026 | C25: 李芷彤 | D25: 2026/03/24 | E25: 上班 | F25: 香港晚班 | G25: 16:00 | H25: 21:00 | I25: 5 | J25: 16:00 | K25: 21:00 | L25: 否
A26: 香港專櫃課 | B26: P0026 | C26: 李芷彤 | D26: 2026/03/25 | E26: 上班 | F26: 香港早班 | G26: 10:30 | H26: 16:30 | I26: 6 | J26: 10:30 | K26: 16:30 | L26: 否
A27: 香港專櫃課 | B27: P0026 | C27: 李芷彤 | D27: 2026/03/26 | E27: 月休 | I27: 0
A28: 香港專櫃課 | B28: P0026 | C28: 李芷彤 | D28: 2026/03/27 | E28: 上班 | F28: 香港ALL班 | G28: 10:30 | H28: 21:00 | I28: 10.5 | J28: 10:30 | K28: 21:00 | L28: 否
A29: 香港專櫃課 | B29: P0026 | C29: 李芷彤 | D29: 2026/03/28 | E29: 上班 | F29: 香港晚班 | G29: 16:00 | H29: 21:00 | I29: 5 | J29: 16:00 | K29: 21:00 | L29: 否
A30: 香港專櫃課 | B30: P0026 | C30: 李芷彤 | D30: 2026/03/29 | E30: 月休 | I30: 0
A31: 香港專櫃課 | B31: P0026 | C31: 李芷彤 | D31: 2026/03/30 | E31: 上班 | F31: 香港晚班 | G31: 16:00 | H31: 21:00 | I31: 5 | J31: 16:00 | K31: 21:00 | L31: 否
A32: 香港專櫃課 | B32: P0026 | C32: 李芷彤 | D32: 2026/03/31 | E32: 月休 | I32: 0
A33: 香港專櫃課 | B33: P0026 | C33: 李芷彤 | D33: 2026/04/01 | E33: 上班 | F33: 香港晚班 | G33: 16:00 | H33: 21:00 | I33: 5 | J33: 16:00 | K33: 21:00 | L33: 否
A34: 香港專櫃課 | B34: P0026 | C34: 李芷彤 | D34: 2026/04/02 | E34: 月休 | I34: 0
A35: 香港專櫃課 | B35: P0026 | C35: 李芷彤 | D35: 2026/04/03 | E35: 上班 | F35: 香港晚班 | G35: 16:00 | H35: 21:00 | I35: 5 | J35: 16:00 | K35: 21:00 | L35: 否
A36: 香港專櫃課 | B36: P0026 | C36: 李芷彤 | D36: 2026/04/04 | E36: 上班 | F36: 特殊晚班 | G36: 14:30 | H36: 19:30 | I36: 5 | J36: 14:30 | K36: 19:30 | L36: 否
A37: 香港專櫃課 | B37: P0026 | C37: 李芷彤 | D37: 2026/04/05 | E37: 月休 | I37: 0
A38: 香港專櫃課 | B38: P0026 | C38: 李芷彤 | D38: 2026/04/06 | E38: 國定假日 | I38: 0
A39: 香港專櫃課 | B39: P0026 | C39: 李芷彤 | D39: 2026/04/07 | E39: 國定假日 | I39: 0
A40: 香港專櫃課 | B40: P0026 | C40: 李芷彤 | D40: 2026/04/08 | E40: 月休 | I40: 0
...
